<?xml version="1.0" ?>
<!-- =================================================================================== -->
<!-- |    This document was autogenerated by xacro from aprs_lab_robots.urdf.xacro     | -->
<!-- |    EDITING THIS FILE BY HAND IS NOT RECOMMENDED                                 | -->
<!-- =================================================================================== -->
<robot name="aprs_lab_robots">
  <link name="world"/>
  <link name="aprs_ur_base_link"/>
  <link name="aprs_fanuc_base_link"/>
  <joint name="ur_world_to_base" type="fixed">
    <origin rpy="0 0 0" xyz="10 0 0"/>
    <parent link="world"/>
    <child link="aprs_ur_base_link"/>
  </joint>
  <joint name="fanuc_world_to_base" type="fixed">
    <origin rpy="0 0 0" xyz="0 0 0"/>
    <parent link="world"/>
    <child link="aprs_fanuc_base_link"/>
  </joint>
  <joint name="franka_world_to_base" type="fixed">
    <origin rpy="0 0 0" xyz="0 0 0"/>
    <parent link="world"/>
    <child link="aprs_franka_base_link"/>
  </joint>
  <!-- <xacro:aprs_ur
    parent="aprs_ur_base_link">
  </xacro:aprs_ur>

  <xacro:aprs_fanuc
    parent="aprs_fanuc_base_link">
  </xacro:aprs_fanuc> -->
  <!-- Inclue franka robot macro -->
  <!-- <xacro:include filename="$(find franka_description)/robots/common/franka_robot.xacro"/> -->
  <!-- safety_distance: Minimum safety distance in [m] by which the collision volumes are expanded and which is enforced during robot motions -->
  <!-- arm_id: Namespace of the robot arm. Serves to differentiate between arms in case of multiple instances. -->
  <!-- joint_limits: description of the joint limits that comes from a YAML file. Example definition: ${xacro.load_yaml('$(find franka_description)/robots/fr3/joint_limits.yaml')} -->
  <!-- kinematics: description of the kinematics that comes from a YAML file. Example definition: ${xacro.load_yaml('$(find franka_description)/robots/fr3/kinematics.yaml')} -->
  <!-- inertials: description of the inertials that comes from a YAML file. Example definition: ${xacro.load_yaml('$(find franka_description)/robots/fr3/inertials.yaml')} -->
  <!-- dynamics: description of the dynamics that comes from a YAML file. Example definition: ${xacro.load_yaml('$(find franka_description)/robots/fr3/dynamics.yaml')} -->
  <link name="aprs_franka_base_link"> 
      </link>
  <joint name="aprs_franka_base_link" type="fixed">
    <parent link="aprs_franka_base_link"/>
    <child link="fr3_link0"/>
    <origin rpy="0 0 0" xyz="0 0 0"/>
  </joint>
  <!-- sub-link defining detailed meshes for collision with environment -->
  <link name="fr3_link0">
    <visual name="fr3_link0_visual">
      <geometry>
        <mesh filename="package://franka_description/meshes/fr3/visual/link0.dae"/>
      </geometry>
    </visual>
    <collision name="fr3_link0_collision">
      <geometry>
        <mesh filename="package://franka_description/meshes/fr3/collision/link0.stl"/>
      </geometry>
    </collision>
    <inertial>
      <origin rpy="0 0 0" xyz="-0.041018 -0.00014 0.049974"/>
      <mass value="0.629769"/>
      <inertia ixx="0.00315" ixy="8.2904e-07" ixz="0.00015" iyy="0.00388" iyz="8.2299e-06" izz="0.004285"/>
    </inertial>
  </link>
  <!-- sub-link defining detailed meshes for collision with environment -->
  <link name="fr3_link1">
    <visual name="fr3_link1_visual">
      <geometry>
        <mesh filename="package://franka_description/meshes/fr3/visual/link1.dae"/>
      </geometry>
    </visual>
    <collision name="fr3_link1_collision">
      <geometry>
        <mesh filename="package://franka_description/meshes/fr3/collision/link1.stl"/>
      </geometry>
    </collision>
    <inertial>
      <origin rpy="0 0 0" xyz="0.003875 0.002081 -0.04762"/>
      <mass value="4.970684"/>
      <inertia ixx="0.70337" ixy="-0.000139" ixz="0.006772" iyy="0.70661" iyz="0.019169" izz="0.009117"/>
    </inertial>
  </link>
  <joint name="fr3_joint1" type="revolute">
    <origin rpy="0 0 0" xyz="0 0 0.333"/>
    <parent link="fr3_link0"/>
    <child link="fr3_link1"/>
    <axis xyz="0 0 1"/>
    <limit effort="87.0" lower="-2.7437" upper="2.7437" velocity="2.62"/>
    <safety_controller k_position="100.0" k_velocity="40.0" soft_lower_limit="-2.7437" soft_upper_limit="2.7437"/>
    <dynamics D="1" K="7000" damping="0.003" friction="0.0" mu_coulomb="0" mu_viscous="16"/>
  </joint>
  <!-- sub-link defining detailed meshes for collision with environment -->
  <link name="fr3_link2">
    <visual name="fr3_link2_visual">
      <geometry>
        <mesh filename="package://franka_description/meshes/fr3/visual/link2.dae"/>
      </geometry>
    </visual>
    <collision name="fr3_link2_collision">
      <geometry>
        <mesh filename="package://franka_description/meshes/fr3/collision/link2.stl"/>
      </geometry>
    </collision>
    <inertial>
      <origin rpy="0 0 0" xyz="-0.003141 -0.02872  0.003495"/>
      <mass value="0.646926"/>
      <inertia ixx="0.007962" ixy="-0.003925" ixz="0.010254" iyy="0.02811" iyz="0.000704" izz="0.025995"/>
    </inertial>
  </link>
  <joint name="fr3_joint2" type="revolute">
    <origin rpy="-1.570796326794897 0 0" xyz="0 0 0"/>
    <parent link="fr3_link1"/>
    <child link="fr3_link2"/>
    <axis xyz="0 0 1"/>
    <limit effort="87.0" lower="-1.7837" upper="1.7837" velocity="2.62"/>
    <safety_controller k_position="100.0" k_velocity="40.0" soft_lower_limit="-1.7837" soft_upper_limit="1.7837"/>
    <dynamics D="1" K="7000" damping="0.003" friction="0.0" mu_coulomb="0" mu_viscous="16"/>
  </joint>
  <!-- sub-link defining detailed meshes for collision with environment -->
  <link name="fr3_link3">
    <visual name="fr3_link3_visual">
      <geometry>
        <mesh filename="package://franka_description/meshes/fr3/visual/link3.dae"/>
      </geometry>
    </visual>
    <collision name="fr3_link3_collision">
      <geometry>
        <mesh filename="package://franka_description/meshes/fr3/collision/link3.stl"/>
      </geometry>
    </collision>
    <inertial>
      <origin rpy="0 0 0" xyz="2.7518e-02 3.9252e-02 -6.6502e-02"/>
      <mass value="3.228604"/>
      <inertia ixx="0.037242" ixy="-0.004761" ixz="-0.011396" iyy="0.036155" iyz="-0.012805" izz="0.01083"/>
    </inertial>
  </link>
  <joint name="fr3_joint3" type="revolute">
    <origin rpy="1.570796326794897 0 0" xyz="0 -0.316 0"/>
    <parent link="fr3_link2"/>
    <child link="fr3_link3"/>
    <axis xyz="0 0 1"/>
    <limit effort="87.0" lower="-2.9007" upper="2.9007" velocity="2.62"/>
    <safety_controller k_position="100.0" k_velocity="40.0" soft_lower_limit="-2.9007" soft_upper_limit="2.9007"/>
    <dynamics D="1" K="7000" damping="0.003" friction="0.0" mu_coulomb="0" mu_viscous="16"/>
  </joint>
  <!-- sub-link defining detailed meshes for collision with environment -->
  <link name="fr3_link4">
    <visual name="fr3_link4_visual">
      <geometry>
        <mesh filename="package://franka_description/meshes/fr3/visual/link4.dae"/>
      </geometry>
    </visual>
    <collision name="fr3_link4_collision">
      <geometry>
        <mesh filename="package://franka_description/meshes/fr3/collision/link4.stl"/>
      </geometry>
    </collision>
    <inertial>
      <origin rpy="0 0 0" xyz="-5.317e-02 1.04419e-01 2.7454e-02"/>
      <mass value="3.587895"/>
      <inertia ixx="0.025853" ixy="0.007796" ixz="-0.001332" iyy="0.019552" iyz="0.008641" izz="0.028323"/>
    </inertial>
  </link>
  <joint name="fr3_joint4" type="revolute">
    <origin rpy="1.570796326794897 0 0" xyz="0.0825 0 0"/>
    <parent link="fr3_link3"/>
    <child link="fr3_link4"/>
    <axis xyz="0 0 1"/>
    <limit effort="87.0" lower="-3.0421" upper="-0.1518" velocity="2.62"/>
    <safety_controller k_position="100.0" k_velocity="40.0" soft_lower_limit="-3.0421" soft_upper_limit="-0.1518"/>
    <dynamics D="1" K="7000" damping="0.003" friction="0.0" mu_coulomb="0" mu_viscous="16"/>
  </joint>
  <!-- sub-link defining detailed meshes for collision with environment -->
  <link name="fr3_link5">
    <visual name="fr3_link5_visual">
      <geometry>
        <mesh filename="package://franka_description/meshes/fr3/visual/link5.dae"/>
      </geometry>
    </visual>
    <collision name="fr3_link5_collision">
      <geometry>
        <mesh filename="package://franka_description/meshes/fr3/collision/link5.stl"/>
      </geometry>
    </collision>
    <inertial>
      <origin rpy="0 0 0" xyz="-1.1953e-02 4.1065e-02 -3.8437e-02"/>
      <mass value="1.225946"/>
      <inertia ixx="0.035549" ixy="-0.002117" ixz="-0.004037" iyy="0.029474" iyz="0.000229" izz="0.008627"/>
    </inertial>
  </link>
  <joint name="fr3_joint5" type="revolute">
    <origin rpy="-1.570796326794897 0 0" xyz="-0.0825 0.384 0"/>
    <parent link="fr3_link4"/>
    <child link="fr3_link5"/>
    <axis xyz="0 0 1"/>
    <limit effort="12.0" lower="-2.8065" upper="2.8065" velocity="5.26"/>
    <safety_controller k_position="100.0" k_velocity="40.0" soft_lower_limit="-2.8065" soft_upper_limit="2.8065"/>
    <dynamics D="1" K="7000" damping="0.003" friction="0.0" mu_coulomb="0" mu_viscous="16"/>
  </joint>
  <!-- sub-link defining detailed meshes for collision with environment -->
  <link name="fr3_link6">
    <visual name="fr3_link6_visual">
      <geometry>
        <mesh filename="package://franka_description/meshes/fr3/visual/link6.dae"/>
      </geometry>
    </visual>
    <collision name="fr3_link6_collision">
      <geometry>
        <mesh filename="package://franka_description/meshes/fr3/collision/link6.stl"/>
      </geometry>
    </collision>
    <inertial>
      <origin rpy="0 0 0" xyz="6.0149e-02 -1.4117e-02 -1.0517e-02"/>
      <mass value="1.666555"/>
      <inertia ixx="0.001964" ixy="0.000109" ixz="-0.001158" iyy="0.004354" iyz="0.000341" izz="0.005433"/>
    </inertial>
  </link>
  <joint name="fr3_joint6" type="revolute">
    <origin rpy="1.570796326794897 0 0" xyz="0 0 0"/>
    <parent link="fr3_link5"/>
    <child link="fr3_link6"/>
    <axis xyz="0 0 1"/>
    <limit effort="12.0" lower="0.5445" upper="4.5169" velocity="4.18"/>
    <safety_controller k_position="100.0" k_velocity="40.0" soft_lower_limit="0.5445" soft_upper_limit="4.5169"/>
    <dynamics D="1" K="7000" damping="0.003" friction="0.0" mu_coulomb="0" mu_viscous="16"/>
  </joint>
  <!-- sub-link defining detailed meshes for collision with environment -->
  <link name="fr3_link7">
    <visual name="fr3_link7_visual">
      <geometry>
        <mesh filename="package://franka_description/meshes/fr3/visual/link7.dae"/>
      </geometry>
    </visual>
    <collision name="fr3_link7_collision">
      <geometry>
        <mesh filename="package://franka_description/meshes/fr3/collision/link7.stl"/>
      </geometry>
    </collision>
    <inertial>
      <origin rpy="0 0 0" xyz="1.0517e-02 -4.252e-03 6.1597e-02"/>
      <mass value="0.735522"/>
      <inertia ixx="0.012516" ixy="-0.000428" ixz="-0.001196" iyy="0.010027" iyz="-0.000741" izz="0.004815"/>
    </inertial>
  </link>
  <joint name="fr3_joint7" type="revolute">
    <origin rpy="1.570796326794897 0 0" xyz="0.088 0 0"/>
    <parent link="fr3_link6"/>
    <child link="fr3_link7"/>
    <axis xyz="0 0 1"/>
    <limit effort="12.0" lower="-3.0159" upper="3.0159" velocity="5.26"/>
    <safety_controller k_position="100.0" k_velocity="40.0" soft_lower_limit="-3.0159" soft_upper_limit="3.0159"/>
    <dynamics D="1" K="7000" damping="0.003" friction="0.0" mu_coulomb="0" mu_viscous="16"/>
  </joint>
  <link name="fr3_link8"/>
  <joint name="fr3_joint8" type="fixed">
    <origin rpy="0 0 0" xyz="0 0 0.107"/>
    <parent link="fr3_link7"/>
    <child link="fr3_link8"/>
  </joint>
  <!-- Run franka macro
    <xacro:franka_robot 
      arm_id="fr3"
      joint_limits="${xacro.load_yaml('$(find franka_description)/robots/fr3/joint_limits.yaml')}"
      inertials="${xacro.load_yaml('$(find franka_description)/robots/fr3/inertials.yaml')}"
      kinematics="${xacro.load_yaml('$(find franka_description)/robots/fr3/kinematics.yaml')}"
      dynamics="${xacro.load_yaml('$(find franka_description)/robots/fr3/dynamics.yaml')}"
      hand="true"
      robot_ip="0.0.0.0">
    </xacro:franka_robot> -->
  <ros2_control name="franka" type="system">
    <hardware>
      <plugin>gz_ros2_control/GazeboSimSystem</plugin>
    </hardware>
    <joint name="fr3_joint1">
      <command_interface name="position">
        <param name="min">-2.7437</param>
        <param name="max">2.7437</param>
      </command_interface>
      <state_interface name="position">
        <param name="initial_value">0.0</param>
      </state_interface>
      <state_interface name="velocity"/>
      <state_interface name="effort"/>
    </joint>
    <joint name="fr3_joint2">
      <command_interface name="position">
        <param name="min">-1.7837</param>
        <param name="max">1.7837</param>
      </command_interface>
      <state_interface name="position">
        <param name="initial_value">0.0</param>
      </state_interface>
      <state_interface name="velocity"/>
      <state_interface name="effort"/>
    </joint>
    <joint name="fr3_joint3">
      <command_interface name="position">
        <param name="min">-2.9007</param>
        <param name="max">2.9007</param>
      </command_interface>
      <state_interface name="position">
        <param name="initial_value">0.0</param>
      </state_interface>
      <state_interface name="velocity"/>
      <state_interface name="effort"/>
    </joint>
    <joint name="fr3_joint4">
      <command_interface name="position">
        <param name="min">-3.0421</param>
        <param name="max">-0.1518</param>
      </command_interface>
      <state_interface name="position">
        <param name="initial_value">-1.57</param>
      </state_interface>
      <state_interface name="velocity"/>
      <state_interface name="effort"/>
    </joint>
    <joint name="fr3_joint5">
      <command_interface name="position">
        <param name="min">-2.8065</param>
        <param name="max">2.8065</param>
      </command_interface>
      <state_interface name="position">
        <param name="initial_value">0.0</param>
      </state_interface>
      <state_interface name="velocity"/>
      <state_interface name="effort"/>
    </joint>
    <joint name="fr3_joint6">
      <command_interface name="position">
        <param name="min">0.5445</param>
        <param name="max">4.5169</param>
      </command_interface>
      <state_interface name="position">
        <param name="initial_value">1.57</param>
      </state_interface>
      <state_interface name="velocity"/>
      <state_interface name="effort"/>
    </joint>
    <joint name="fr3_joint7">
      <command_interface name="position">
        <param name="min">-3.0159</param>
        <param name="max">3.0159</param>
      </command_interface>
      <state_interface name="position">
        <param name="initial_value">0.0</param>
      </state_interface>
      <state_interface name="velocity"/>
      <state_interface name="effort"/>
    </joint>
  </ros2_control>
  <gazebo>
    <plugin filename="libgz_ros2_control-system.so" name="gz_ros2_control::GazeboSimROS2ControlPlugin">
      <ros>
      </ros>
      <parameters>/home/ubuntu/aprs_ws/install/aprs_description/share/aprs_description/config/robot_controllers.yaml</parameters>
    </plugin>
  </gazebo>
</robot>
