<?xml version="1.0" ?>
<sdf version="1.6">
  <model name="conveyor_belt">
      <static>false</static>

      <link name="conveyor_base">

        <visual name="conveyor_base_visual">
          <pose>-0.15 -0.6 0.35 0 0 0</pose>
          <geometry>
            <box>
              <size> 3.05 0.65 0.7 </size>
            </box>
            <!-- <mesh>
              <uri>model://conveyor_belt/meshes/revised_conveyor.stl</uri>
            </mesh> -->
          </geometry>
          <material>
              <ambient>0.0 0.0 0.0 1.0</ambient>
              <diffuse>0.5 0.5 0.5 1.0</diffuse>
          </material>
        </visual>
        <collision name="conveyor_base_collision">
          <pose>-0.15 -0.6 0.35 0 0 0</pose>
          <geometry>
            <box>
              <size> 3.05 0.65 0.7 </size>
            </box>
          </geometry>
        </collision>
      </link>

      <link name="conveyor_belt">

        <visual name="conveyor_belt_visual">
          <pose>-0.15 -0.6 0.85 0 0 0</pose>
          <geometry>
            <box>
              <size> 3.05 0.5 0.1 </size>
            </box>
            <!-- <mesh>
              <uri>model://conveyor/meshes/revised_conveyor.stl</uri>
            </mesh> -->
          </geometry>
          <material>
              <ambient>0.0 0.0 0.0 1.0</ambient>
              <diffuse>0.1 0.1 0.1 1.0</diffuse>
          </material>
        </visual>
        <collision name="conveyor_belt_collision">
          <pose>-0.15 -0.6 0.85 0 0 0</pose>
          <geometry>
            <box>
              <size> 3.05 0.5 0.1 </size>
            </box>
          </geometry>
        </collision>
      </link>

      <joint name="belt_joint" type="prismatic">
        <parent>conveyor_base</parent>
        <child>conveyor_belt</child>
        <axis>
          <xyz>1 0 0</xyz>
          <limit>
            <lower>-0.4</lower>
            <upper>0.4</upper>
            <effort>100</effort>
          </limit>
        </axis>
      </joint>

      <plugin
        filename="libConveyorPlugin.so"
        name="aprs_plugins::ConveyorPlugin">
        <max_velocity>0.2</max_velocity>
      </plugin>
    
    </model>

</sdf>